Workbook

Sheet Synthèse
A1: Suivi des tests manuels — Minidisc
A2: La synthèse se met à jour automatiquement depuis la colonne Statut de l’onglet Checklist.
A4: Tests au total | C4: À tester | E4: Tests OK | G4: Avancement
A5: =COUNTA(Checklist!$A$5:$A$172) -> 168 | C5: =COUNTIF(Checklist!$G$5:$G$172,"À tester") -> 168 | E5: =COUNTIF(Checklist!$G$5:$G$172,"OK") -> 0 | G5: =IF(COUNTA(Checklist!$A$5:$A$172)=0,0,(COUNTA(Checklist!$A$5:$A$172)-COUNTIF(Checklist!$G$5:$G$172,"À tester"))/COUNTA(Checklist!$A$5:$A$172)) -> 0
A9: Répartition par priorité | F9: Répartition par statut
A10: Priorité | B10: Total | C10: OK | D10: Avancement | F10: Statut | G10: Nombre
A11: P0 | B11: =COUNTIF(Checklist!$B$5:$B$172,A11) -> 71 | C11: =COUNTIFS(Checklist!$B$5:$B$172,A11,Checklist!$G$5:$G$172,"OK") -> 0 | D11: =IF(B11=0,0,(B11-COUNTIFS(Checklist!$B$5:$B$172,A11,Checklist!$G$5:$G$172,"À tester"))/B11) -> 0 | F11: À tester | G11: =COUNTIF(Checklist!$G$5:$G$172,F11) -> 168
A12: P1 | B12: =COUNTIF(Checklist!$B$5:$B$172,A12) -> 68 | C12: =COUNTIFS(Checklist!$B$5:$B$172,A12,Checklist!$G$5:$G$172,"OK") -> 0 | D12: =IF(B12=0,0,(B12-COUNTIFS(Checklist!$B$5:$B$172,A12,Checklist!$G$5:$G$172,"À tester"))/B12) -> 0 | F12: En cours | G12: =COUNTIF(Checklist!$G$5:$G$172,F12) -> 0
A13: P2 | B13: =COUNTIF(Checklist!$B$5:$B$172,A13) -> 29 | C13: =COUNTIFS(Checklist!$B$5:$B$172,A13,Checklist!$G$5:$G$172,"OK") -> 0 | D13: =IF(B13=0,0,(B13-COUNTIFS(Checklist!$B$5:$B$172,A13,Checklist!$G$5:$G$172,"À tester"))/B13) -> 0 | F13: OK | G13: =COUNTIF(Checklist!$G$5:$G$172,F13) -> 0
F14: Échec | G14: =COUNTIF(Checklist!$G$5:$G$172,F14) -> 0
F15: Bloqué | G15: =COUNTIF(Checklist!$G$5:$G$172,F15) -> 0
F16: N/A | G16: =COUNTIF(Checklist!$G$5:$G$172,F16) -> 0
A18: Progression par catégorie | G18: Mode d’emploi
A19: Catégorie | B19: Total | C19: OK | D19: Échec | E19: Bloqué | F19: Traité | G19: 1. Renseigner l’onglet Préparation. 2. Exécuter les P0 en premier. 3. Choisir un statut dans la Checklist. 4. Documenter toute anomalie dans Notes. 5. Filtrer par priorité, catégorie ou statut.
A20: Lecture & seek | B20: =COUNTIF(Checklist!$C$5:$C$172,A20) -> 12 | C20: =COUNTIFS(Checklist!$C$5:$C$172,A20,Checklist!$G$5:$G$172,"OK") -> 0 | D20: =COUNTIFS(Checklist!$C$5:$C$172,A20,Checklist!$G$5:$G$172,"Échec") -> 0 | E20: =COUNTIFS(Checklist!$C$5:$C$172,A20,Checklist!$G$5:$G$172,"Bloqué") -> 0 | F20: =IF(B20=0,0,(B20-COUNTIFS(Checklist!$C$5:$C$172,A20,Checklist!$G$5:$G$172,"À tester"))/B20) -> 0
A21: Durée & fin | B21: =COUNTIF(Checklist!$C$5:$C$172,A21) -> 9 | C21: =COUNTIFS(Checklist!$C$5:$C$172,A21,Checklist!$G$5:$G$172,"OK") -> 0 | D21: =COUNTIFS(Checklist!$C$5:$C$172,A21,Checklist!$G$5:$G$172,"Échec") -> 0 | E21: =COUNTIFS(Checklist!$C$5:$C$172,A21,Checklist!$G$5:$G$172,"Bloqué") -> 0 | F21: =IF(B21=0,0,(B21-COUNTIFS(Checklist!$C$5:$C$172,A21,Checklist!$G$5:$G$172,"À tester"))/B21) -> 0
A22: File & navigation | B22: =COUNTIF(Checklist!$C$5:$C$172,A22) -> 10 | C22: =COUNTIFS(Checklist!$C$5:$C$172,A22,Checklist!$G$5:$G$172,"OK") -> 0 | D22: =COUNTIFS(Checklist!$C$5:$C$172,A22,Checklist!$G$5:$G$172,"Échec") -> 0 | E22: =COUNTIFS(Checklist!$C$5:$C$172,A22,Checklist!$G$5:$G$172,"Bloqué") -> 0 | F22: =IF(B22=0,0,(B22-COUNTIFS(Checklist!$C$5:$C$172,A22,Checklist!$G$5:$G$172,"À tester"))/B22) -> 0
A23: Repeat & shuffle | B23: =COUNTIF(Checklist!$C$5:$C$172,A23) -> 8 | C23: =COUNTIFS(Checklist!$C$5:$C$172,A23,Checklist!$G$5:$G$172,"OK") -> 0 | D23: =COUNTIFS(Checklist!$C$5:$C$172,A23,Checklist!$G$5:$G$172,"Échec") -> 0 | E23: =COUNTIFS(Checklist!$C$5:$C$172,A23,Checklist!$G$5:$G$172,"Bloqué") -> 0 | F23: =IF(B23=0,0,(B23-COUNTIFS(Checklist!$C$5:$C$172,A23,Checklist!$G$5:$G$172,"À tester"))/B23) -> 0
A24: Crossfade | B24: =COUNTIF(Checklist!$C$5:$C$172,A24) -> 11 | C24: =COUNTIFS(Checklist!$C$5:$C$172,A24,Checklist!$G$5:$G$172,"OK") -> 0 | D24: =COUNTIFS(Checklist!$C$5:$C$172,A24,Checklist!$G$5:$G$172,"Échec") -> 0 | E24: =COUNTIFS(Checklist!$C$5:$C$172,A24,Checklist!$G$5:$G$172,"Bloqué") -> 0 | F24: =IF(B24=0,0,(B24-COUNTIFS(Checklist!$C$5:$C$172,A24,Checklist!$G$5:$G$172,"À tester"))/B24) -> 0
A25: Gapless | B25: =COUNTIF(Checklist!$C$5:$C$172,A25) -> 8 | C25: =COUNTIFS(Checklist!$C$5:$C$172,A25,Checklist!$G$5:$G$172,"OK") -> 0 | D25: =COUNTIFS(Checklist!$C$5:$C$172,A25,Checklist!$G$5:$G$172,"Échec") -> 0 | E25: =COUNTIFS(Checklist!$C$5:$C$172,A25,Checklist!$G$5:$G$172,"Bloqué") -> 0 | F25: =IF(B25=0,0,(B25-COUNTIFS(Checklist!$C$5:$C$172,A25,Checklist!$G$5:$G$172,"À tester"))/B25) -> 0
A26: ReplayGain | B26: =COUNTIF(Checklist!$C$5:$C$172,A26) -> 13 | C26: =COUNTIFS(Checklist!$C$5:$C$172,A26,Checklist!$G$5:$G$172,"OK") -> 0 | D26: =COUNTIFS(Checklist!$C$5:$C$172,A26,Checklist!$G$5:$G$172,"Échec") -> 0 | E26: =COUNTIFS(Checklist!$C$5:$C$172,A26,Checklist!$G$5:$G$172,"Bloqué") -> 0 | F26: =IF(B26=0,0,(B26-COUNTIFS(Checklist!$C$5:$C$172,A26,Checklist!$G$5:$G$172,"À tester"))/B26) -> 0
A27: Control Center | B27: =COUNTIF(Checklist!$C$5:$C$172,A27) -> 10 | C27: =COUNTIFS(Checklist!$C$5:$C$172,A27,Checklist!$G$5:$G$172,"OK") -> 0 | D27: =COUNTIFS(Checklist!$C$5:$C$172,A27,Checklist!$G$5:$G$172,"Échec") -> 0 | E27: =COUNTIFS(Checklist!$C$5:$C$172,A27,Checklist!$G$5:$G$172,"Bloqué") -> 0 | F27: =IF(B27=0,0,(B27-COUNTIFS(Checklist!$C$5:$C$172,A27,Checklist!$G$5:$G$172,"À tester"))/B27) -> 0
A28: Session audio & routes | B28: =COUNTIF(Checklist!$C$5:$C$172,A28) -> 11 | C28: =COUNTIFS(Checklist!$C$5:$C$172,A28,Checklist!$G$5:$G$172,"OK") -> 0 | D28: =COUNTIFS(Checklist!$C$5:$C$172,A28,Checklist!$G$5:$G$172,"Échec") -> 0 | E28: =COUNTIFS(Checklist!$C$5:$C$172,A28,Checklist!$G$5:$G$172,"Bloqué") -> 0 | F28: =IF(B28=0,0,(B28-COUNTIFS(Checklist!$C$5:$C$172,A28,Checklist!$G$5:$G$172,"À tester"))/B28) -> 0
A29: Restauration | B29: =COUNTIF(Checklist!$C$5:$C$172,A29) -> 8 | C29: =COUNTIFS(Checklist!$C$5:$C$172,A29,Checklist!$G$5:$G$172,"OK") -> 0 | D29: =COUNTIFS(Checklist!$C$5:$C$172,A29,Checklist!$G$5:$G$172,"Échec") -> 0 | E29: =COUNTIFS(Checklist!$C$5:$C$172,A29,Checklist!$G$5:$G$172,"Bloqué") -> 0 | F29: =IF(B29=0,0,(B29-COUNTIFS(Checklist!$C$5:$C$172,A29,Checklist!$G$5:$G$172,"À tester"))/B29) -> 0
A30: Téléchargements | B30: =COUNTIF(Checklist!$C$5:$C$172,A30) -> 12 | C30: =COUNTIFS(Checklist!$C$5:$C$172,A30,Checklist!$G$5:$G$172,"OK") -> 0 | D30: =COUNTIFS(Checklist!$C$5:$C$172,A30,Checklist!$G$5:$G$172,"Échec") -> 0 | E30: =COUNTIFS(Checklist!$C$5:$C$172,A30,Checklist!$G$5:$G$172,"Bloqué") -> 0 | F30: =IF(B30=0,0,(B30-COUNTIFS(Checklist!$C$5:$C$172,A30,Checklist!$G$5:$G$172,"À tester"))/B30) -> 0
A31: Offline partagé | B31: =COUNTIF(Checklist!$C$5:$C$172,A31) -> 7 | C31: =COUNTIFS(Checklist!$C$5:$C$172,A31,Checklist!$G$5:$G$172,"OK") -> 0 | D31: =COUNTIFS(Checklist!$C$5:$C$172,A31,Checklist!$G$5:$G$172,"Échec") -> 0 | E31: =COUNTIFS(Checklist!$C$5:$C$172,A31,Checklist!$G$5:$G$172,"Bloqué") -> 0 | F31: =IF(B31=0,0,(B31-COUNTIFS(Checklist!$C$5:$C$172,A31,Checklist!$G$5:$G$172,"À tester"))/B31) -> 0
... A37: Smoke test | B37: =COUNTIF(Checklist!$C$5:$C$172,A37) -> 8 | C37: =COUNTIFS(Checklist!$C$5:$C$172,A37,Checklist!$G$5:$G$172,"OK") -> 0 | D37: =COUNTIFS(Checklist!$C$5:$C$172,A37,Checklist!$G$5:$G$172,"Échec") -> 0 | E37: =COUNTIFS(Checklist!$C$5:$C$172,A37,Checklist!$G$5:$G$172,"Bloqué") -> 0 | F37: =IF(B37=0,0,(B37-COUNTIFS(Checklist!$C$5:$C$172,A37,Checklist!$G$5:$G$172,"À tester"))/B37) -> 0

Sheet Checklist
A1: Checklist de tests manuels — Minidisc
A2: Commencer par les P0. Utiliser le menu Statut, saisir les anomalies dans Notes et dater chaque exécution.
A4: ID | B4: Priorité | C4: Catégorie | D4: Test manuel | E4: Résultat attendu | F4: Configuration / Source | G4: Statut | H4: Notes / anomalie | I4: Date du test
A5: T001 | B5: P0 | C5: Lecture & seek | D5: Lancer un morceau depuis l’arrêt complet. | E5: Le son démarre rapidement, sans délai artificiel perceptible. | F5: Toutes sources | G5: À tester
A6: T002 | B6: P0 | C6: Lecture & seek | D6: Mettre en pause puis reprendre depuis le player. | E6: La lecture repart exactement au bon endroit. | F6: Toutes sources | G6: À tester
A7: T003 | B7: P0 | C7: Lecture & seek | D7: Déplacer le curseur en avant pendant la lecture. | E7: Le son saute réellement à la position demandée et l’UI reste synchronisée. | F7: Toutes sources | G7: À tester
A8: T004 | B8: P0 | C8: Lecture & seek | D8: Déplacer le curseur en arrière pendant la lecture. | E8: Le son et l’UI reviennent à la bonne position. | F8: Toutes sources | G8: À tester
A9: T005 | B9: P0 | C9: Lecture & seek | D9: Faire un seek pendant que le morceau est en pause, puis reprendre. | E9: La reprise commence à la nouvelle position, sans lecture intermédiaire. | F9: Toutes sources | G9: À tester
A10: T006 | B10: P0 | C10: Lecture & seek | D10: Effectuer plusieurs seeks rapides dans les deux directions. | E10: Seule la dernière demande gagne ; aucun retour retardé à une ancienne position. | F10: Toutes sources | G10: À tester
A11: T007 | B11: P0 | C11: Lecture & seek | D11: Faire un seek très près de zéro. | E11: La lecture rejoint proprement le début, sans blocage. | F11: Toutes sources | G11: À tester
A12: T008 | B12: P0 | C12: Lecture & seek | D12: Faire un seek très près de la fin. | E12: La lecture rejoint la fin réelle et la transition ne se déclenche qu’une fois. | F12: Toutes sources | G12: À tester
A13: T009 | B13: P0 | C13: Lecture & seek | D13: Faire un seek depuis les paroles synchronisées. | E13: Le son et le curseur se positionnent sur la ligne choisie. | F13: Piste avec paroles synchronisées | G13: À tester
A14: T010 | B14: P0 | C14: Lecture & seek | D14: Faire des seeks depuis l’écran verrouillé ou le Control Center. | E14: L’app et le Control Center affichent ensuite la même position. | F14: iPhone verrouillé | G14: À tester
A15: T011 | B15: P0 | C15: Lecture & seek | D15: Rouvrir l’app après un seek effectué dans le Control Center. | E15: Les deux curseurs correspondent et le son est au bon endroit. | F15: iPhone verrouillé | G15: À tester
A16: T012 | B16: P0 | C16: Lecture & seek | D16: Faire un seek alors que la piste suivante est préchargée. | E16: Aucune double lecture, aucun changement de morceau retardé. | F16: Crossfade activé | G16: À tester
... A25: T021 | B25: P0 | C25: Durée & fin | D25: Appuyer sur Suivant en étant déjà sur le dernier morceau. | E25: Arrêt propre, sans lecture fantôme ni retour silencieux au premier titre. | F25: Repeat Off | G25: À tester
A26: T022 | B26: P0 | C26: File & navigation | D26: Utiliser Suivant depuis l’app. | E26: La piste suivante de la file devient la piste courante. | G26: À tester
A27: T023 | B27: P0 | C27: File & navigation | D27: Utiliser Suivant depuis le Control Center. | E27: Même résultat que depuis l’app, sans délai ni double transition. | F27: Écran verrouillé | G27: À tester
A28: T024 | B28: P0 | C28: File & navigation | D28: Utiliser Précédent après plus de 3 secondes de lecture. | E28: Le morceau courant redémarre au début. | G28: À tester
A29: T025 | B29: P0 | C29: File & navigation | D29: Utiliser Précédent dans les 3 premières secondes. | E29: La lecture revient au morceau précédent. | G29: À tester
A30: T026 | B30: P0 | C30: File & navigation | D30: Tester Précédent depuis le Control Center avant et après 3 secondes. | E30: La règle des 3 secondes reste identique à celle de l’app. | F30: Écran verrouillé | G30: À tester
A31: T027 | B31: P0 | C31: File & navigation | D31: Appuyer rapidement plusieurs fois sur Suivant. | E31: Le morceau final demandé gagne ; aucune ancienne résolution ne reprend la main. | F31: Réseau volontairement lent si possible | G31: À tester
A32: T028 | B32: P0 | C32: File & navigation | D32: Sélectionner rapidement deux morceaux différents dans la file. | E32: Seul le dernier morceau sélectionné finit par jouer. | F32: Réseau volontairement lent si possible | G32: À tester
A33: T029 | B33: P0 | C33: File & navigation | D33: Placer deux occurrences du même morceau dans la file. | E33: Les deux occurrences sont jouées correctement et séparément. | G33: À tester
A34: T030 | B34: P0 | C34: File & navigation | D34: Réordonner des morceaux puis utiliser Suivant et Précédent. | E34: L’ordre réellement joué correspond à l’ordre visible. | G34: À tester
A35: T031 | B35: P0 | C35: File & navigation | D35: Supprimer un morceau à venir pendant la lecture. | E35: La transition suivante reste correcte et la file n’est pas corrompue. | G35: À tester
A36: T032 | B36: P0 | C36: Repeat & shuffle | D36: Lire une file complète avec Repeat Off. | E36: Le player s’arrête à la fin. | F36: Repeat Off | G36: À tester
A37: T033 | B37: P0 | C37: Repeat & shuffle | D37: Laisser finir un morceau avec Repeat One. | E37: Le même morceau recommence sans passer au suivant. | F37: Repeat One | G37: À tester
A38: T034 | B38: P0 | C38: Repeat & shuffle | D38: Observer plusieurs boucles en Repeat One. | E38: Chaque boucle repart réellement du début et ne double pas l’audio. | F38: Repeat One | G38: À tester
A39: T035 | B39: P0 | C39: Repeat & shuffle | D39: Laisser finir la file avec Repeat All. | E39: Après le dernier morceau, la lecture reprend au premier. | F39: Repeat All | G39: À tester
A40: T036 | B40: P0 | C40: Repeat & shuffle | D40: Activer Shuffle en cours de lecture. | E40: Le morceau courant et l’historique ne bougent pas ; seuls les titres à venir changent. | G40: À tester
A41: T037 | B41: P0 | C41: Repeat & shuffle | D41: Désactiver Shuffle. | E41: L’ordre initial revient et le bon morceau reste courant. | G41: À tester
A42: T038 | B42: P0 | C42: Repeat & shuffle | D42: Activer puis désactiver Shuffle après avoir déplacé des morceaux. | E42: La file reste cohérente et ne perd aucun morceau. | G42: À tester
A43: T039 | B43: P0 | C43: Repeat & shuffle | D43: Démarrer une nouvelle file pendant Shuffle ou Smart Shuffle. | E43: La nouvelle file remplace proprement l’ancienne et l’ancien mode se termine. | G43: À tester
A44: T040 | B44: P0 | C44: Crossfade | D44: Laisser une transition naturelle avec Crossfade désactivé. | E44: Aucune superposition audible ; la transition reste propre. | F44: Crossfade Off | G44: À tester
A45: T041 | B45: P0 | C45: Crossfade | D45: Laisser une transition naturelle entre deux morceaux non consécutifs d’un album. | E45: Le chevauchement audible correspond approximativement à la durée configurée. | F45: Crossfade 5–6 s | G45: À tester
A46: T042 | B46: P0 | C46: Crossfade | D46: Écouter le début du morceau entrant pendant le fondu. | E46: Il commence au bon endroit, sans silence anormal. | F46: Crossfade 5–6 s | G46: À tester
A47: T043 | B47: P0 | C47: Crossfade | D47: Écouter toute la zone de fondu. | E47: Aucun trou, clic, double démarrage ou coupure. | F47: Crossfade 5–6 s | G47: À tester
A48: T044 | B48: P0 | C48: Crossfade | D48: Écouter la fin du fondu. | E48: Le morceau sortant disparaît progressivement, sans saut de volume au hand-off. | F48: Crossfade 5–6 s | G48: À tester
A49: T045 | B49: P0 | C49: Crossfade | D49: Tester une transition entre deux morceaux streamés. | E49: Le crossfade est complet et stable. | F49: Streaming | G49: À tester
...

Sheet Préparation
A1: Préparation de la campagne de tests
A3: Environnement
A4: Build / commit testé
A5: Appareil
A6: Version iOS
A7: Serveur principal
A8: Connexion | B8: Wi‑Fi / 4G / 5G
A9: Casque / route audio
A10: Testeur
A11: Date de campagne
A13: Jeu de données recommandé
A14: Élément | B14: Référence à renseigner | C14: But | D14: Obligatoire
A15: File de 3 morceaux | C15: Transitions, navigation et fin de file | D15: Oui
A16: Morceau à durée problématique | C16: Régression du curseur arrivé à la fin | D16: Oui
A17: Album réellement gapless | C17: Continuité et trim des silences | D17: Oui
A18: Deux pistes avec ReplayGain différent | C18: Normalisation et crossfade | D18: Oui
A19: Piste sans ReplayGain | C19: Comportement de repli | D19: Oui
A20: Album et playlists partageant des pistes | C20: Référencement offline | D20: Oui
A21: Radio internet externe | C21: Commandes live et isolation des headers | D21: Oui
A22: Gros fichier original | C22: Timeout de téléchargement | D22: Recommandé
A23: Deux serveurs configurés | C23: Isolation des données locales | D23: Optionnel
A24: AirPods / casque Bluetooth | C24: Routes et interruptions | D24: Oui
A26: Filtres Console utiles
A27: [SEEK] [CROSSFADE] [REPLAYGAIN] [STATS] [TRANSITION]
A28: Commencer par les P0, puis Téléchargements / Offline partagé, Restauration, et enfin P1 / P2.
